Workbook
Name Slicer_Status: #N/A

Sheet START HERE
B2: Excel Mastery in 90 Minutes
B3: From Formulas to Pivot Tables to Charts — A Hands-On Tutorial
B6: ⏱️ TIME | C6: 📋 TOPIC | F6: 📝 SHEET NAME | L6: 1
B7: 0:00 - 0:05 | C7: Welcome & Dataset Walkthrough | F7: 📊 Sales Data | L7: 5
B8: 0:05 - 0:15 | C8: SUM, SUMIF, SUMIFS | F8: 1️⃣ SUM Functions
B9: 0:15 - 0:25 | C9: COUNT, COUNTIF, COUNTIFS | F9: 2️⃣ COUNT Functions
B10: 0:25 - 0:35 | C10: AVERAGE, AVERAGEIF, MIN, MAX | F10: 3️⃣ AVERAGE MIN MAX
B11: 0:35 - 0:45 | C11: IF, Nested IF, IFS, AND, OR | F11: 4️⃣ IF Functions
B12: 0:45 - 0:55 | C12: VLOOKUP & XLOOKUP | F12: 5️⃣ VLOOKUP XLOOKUP
B13: 0:55 - 1:05 | C13: TEXT Functions (LEFT, RIGHT, MID, CONCAT, TRIM) | F13: 6️⃣ TEXT Functions
B14: 1:05 - 1:15 | C14: Pivot Tables — Build & Analyze | F14: 7️⃣ Pivot Tables
B15: 1:15 - 1:25 | C15: Charts — Visualize Your Data | F15: 8️⃣ Charts
B16: 1:25 - 1:30 | C16: Wrap-Up & Q&A | F16: —
B17: 💡 Tip: Each formula sheet has → USE CASE (why you need it) → SYNTAX → LIVE DEMO → TRY IT YOURSELF section
C23: Column1 | D23: Column2 | E23: Column3 | F23: Column4 | G23: Column5
C24: sdfdsf | D24: sdfdsf | E24: sdfdsf | F24: sdfdsf | G24: 12
C25: sdfdsf | D25: sdfdsf | E25: sdfdsf | F25: sdfdsf | G25: 12
C26: sdfdsf | D26: sdfdsf | E26: sdfdsf | F26: sdfdsf | G26: 12
C27: sdfdsf | D27: sdfdsf | E27: sdfdsf | F27: sdfdsf | G27: 12
C28: sdfdsf | D28: sdfdsf | E28: sdfdsf | F28: sdfdsf | G28: 12
C29: sdfdsf | D29: sdfdsf | E29: sdfdsf | F29: sdfdsf | G29: 12
C30: sdfdsf | D30: sdfdsf | E30: sdfdsf | F30: sdfdsf | G30: 12
C31: sdfdsf | D31: sdfdsf | E31: sdfdsf | F31: sdfdsf | G31: 12
C32: fdgfdg | G32: 12
C33: dfgfd | G33: 12
C34: Total | G34: =SUBTOTAL(105,Table1[Column5]) -> 12

Sheet Sales Data
M1: Furniture | N1: =SUMIFS(Table2[Final Amount ($)],Table2[Category],M1,Table2[Status],"Delivered") -> 11527.95
A3: Order ID | B3: Order Date | C3: Customer Name | D3: Email | E3: City | F3: State | G3: Product | H3: Category | I3: Unit Price ($) | J3: Quantity | K3: Discount % | L3: Total Before Discount ($) | M3: Discount Amount ($) | N3: Final Amount ($) | O3: Status | P3: Sales Rep | Q3: Payment Method
A4: ORD-1084 | B4: 45704 | C4: Ryan Nguyen | D4: ryan@email.com | E4: Adelaide | F4: SA | G4: Laptop | H4: Electronics | I4: 899.99 | J4: 5 | K4: 0 | L4: =I4*J4 -> 4499.95 | M4: =L4*K4 -> 0 | N4: =L4-M4 -> 4499.95 | O4: Delivered | P4: Bob Smith | Q4: Credit Card | T4: What is the total revenue from Office Supplies?
A5: ORD-1081 | B5: 45948 | C5: Lisa Wang | D5: lisa@email.com | E5: Melbourne | F5: VIC | G5: Laptop | H5: Electronics | I5: 899.99 | J5: 5 | K5: 0.1 | L5: =I5*J5 -> 4499.95 | M5: =L5*K5 -> 449.995 | N5: =L5-M5 -> 4049.955 | O5: Processing | P5: Alice Morgan | Q5: Credit Card
A6: ORD-1059 | B6: 46005 | C6: Anna Garcia | D6: anna@email.com | E6: Sydney | F6: NSW | G6: Laptop | H6: Electronics | I6: 899.99 | J6: 5 | K6: 0.15 | L6: =I6*J6 -> 4499.95 | M6: =L6*K6 -> 674.9925 | N6: =L6-M6 -> 3824.9575 | O6: Processing | P6: Bob Smith | Q6: Bank Transfer
A7: ORD-1088 | B7: 45707 | C7: Priya Patel | D7: priya@email.com | E7: Adelaide | F7: SA | G7: Laptop | H7: Electronics | I7: 899.99 | J7: 5 | K7: 0.15 | L7: =I7*J7 -> 4499.95 | M7: =L7*K7 -> 674.9925 | N7: =L7-M7 -> 3824.9575 | O7: Delivered | P7: Dan Wilson | Q7: PayPal
A8: ORD-1077 | B8: 45883 | C8: James Lee | D8: james@email.com | E8: Perth | F8: WA | G8: Laptop | H8: Electronics | I8: 899.99 | J8: 4 | K8: 0.05 | L8: =I8*J8 -> 3599.96 | M8: =L8*K8 -> 179.998 | N8: =L8-M8 -> 3419.962 | O8: Returned | P8: Alice Morgan | Q8: Credit Card
A9: ORD-1001 | B9: 45965 | C9: Ryan Nguyen | D9: ryan@email.com | E9: Adelaide | F9: SA | G9: Laptop | H9: Electronics | I9: 899.99 | J9: 3 | K9: 0 | L9: =I9*J9 -> 2699.97 | M9: =L9*K9 -> 0 | N9: =L9-M9 -> 2699.97 | O9: Delivered | P9: Bob Smith | Q9: Credit Card
A10: ORD-1068 | B10: 45703 | C10: Sophie Martin | D10: sophie@email.com | E10: Melbourne | F10: VIC | G10: Standing Desk | H10: Furniture | I10: 499.99 | J10: 5 | K10: 0 | L10: =I10*J10 -> 2499.95 | M10: =L10*K10 -> 0 | N10: =L10-M10 -> 2499.95 | O10: Processing | P10: Dan Wilson | Q10: Credit Card
A11: ORD-1078 | B11: 45854 | C11: Tom Brown | D11: tom@email.com | E11: Sydney | F11: NSW | G11: Laptop | H11: Electronics | I11: 899.99 | J11: 3 | K11: 0.2 | L11: =I11*J11 -> 2699.97 | M11: =L11*K11 -> 539.994 | N11: =L11-M11 -> 2159.976 | O11: Delivered | P11: Dan Wilson | Q11: Credit Card
A12: ORD-1052 | B12: 45730 | C12: Emma Wilson | D12: emma@email.com | E12: Brisbane | F12: QLD | G12: Laptop | H12: Electronics | I12: 899.99 | J12: 3 | K12: 0.2 | L12: =I12*J12 -> 2699.97 | M12: =L12*K12 -> 539.994 | N12: =L12-M12 -> 2159.976 | O12: Delivered | P12: Bob Smith | Q12: Bank Transfer
A13: ORD-1039 | B13: 45707 | C13: Chris Taylor | D13: chris@email.com | E13: Perth | F13: WA | G13: Monitor 27" | H13: Electronics | I13: 349.99 | J13: 5 | K13: 0 | L13: =I13*J13 -> 1749.95 | M13: =L13*K13 -> 0 | N13: =L13-M13 -> 1749.95 | O13: Shipped | P13: Alice Morgan | Q13: Credit Card
A14: ORD-1003 | B14: 45695 | C14: Anna Garcia | D14: anna@email.com | E14: Sydney | F14: NSW | G14: Monitor 27" | H14: Electronics | I14: 349.99 | J14: 5 | K14: 0 | L14: =I14*J14 -> 1749.95 | M14: =L14*K14 -> 0 | N14: =L14-M14 -> 1749.95 | O14: Shipped | P14: Bob Smith | Q14: Credit Card
A15: ORD-1080 | B15: 45870 | C15: Tom Brown | D15: tom@email.com | E15: Sydney | F15: NSW | G15: Standing Desk | H15: Furniture | I15: 499.99 | J15: 4 | K15: 0.15 | L15: =I15*J15 -> 1999.96 | M15: =L15*K15 -> 299.994 | N15: =L15-M15 -> 1699.966 | O15: Delivered | P15: Dan Wilson | Q15: PayPal
A16: ORD-1062 | B16: 45723 | C16: Sophie Martin | D16: sophie@email.com | E16: Melbourne | F16: VIC | G16: Standing Desk | H16: Furniture | I16: 499.99 | J16: 4 | K16: 0.15 | L16: =I16*J16 -> 1999.96 | M16: =L16*K16 -> 299.994 | N16: =L16-M16 -> 1699.966 | O16: Processing | P16: Bob Smith | Q16: Credit Card
... A104: ORD-1010 | B104: 45970 | C104: Sophie Martin | D104: sophie@email.com | E104: Melbourne | F104: VIC | G104: Pen Set | H104: Office Supplies | I104: 8.99 | J104: 1 | K104: 0.1 | L104: =I104*J104 -> 8.99 | M104: =L104*K104 -> 0.899 | N104: =L104-M104 -> 8.091 | O104: Processing | P104: Bob Smith | Q104: Credit Card
A105: ORD-1073 | B105: 46019 | C105: David Kim | D105: david@email.com | E105: Brisbane | F105: QLD | G105: Desk Lamp | H105: Furniture | I105: 39.99 | J105: 3 | K105: 0.2 | L105: =I105*J105 -> 119.97 | M105: =L105*K105 -> 23.994 | O105: Delivered | P105: Carol Davis | Q105: Credit Card
A106: Total | I106: =SUBTOTAL(101,Table2[Unit Price ($)]) -> 215.37235 | J106: =SUBTOTAL(109,Table2[Quantity]) -> 318 | Q106: =SUBTOTAL(103,Table2[Payment Method]) -> 102

Sheet Sheet1
A1: Category | B1: Product | C1: SUM | D1: Count | E1: CountA | F1: Countif | G1: countifs | H1: Latest Order Value Product | K1: Products | L1: Final Amount
A2: Electronics | B2: Webcam HD | C2: =SUMIFS(Table2[Final Amount ($)],Table2[Category],Sheet1!A2,Table2[Product],Sheet1!B2) -> 542.4225 | F2: =COUNTIF(Table2[Category],Sheet1!A2) -> 46 | G2: =COUNTIFS(Table2[Category],Sheet1!A2,Table2[Product],Sheet1!B2) -> 3 | H2: =VLOOKUP(B2,'Sales Data'!G:N,8,0) -> 279.96 | K2: Laptop | L2: 26639.704
A3: Electronics | B3: Monitor 27" | C3: =SUMIFS(Table2[Final Amount ($)],Table2[Category],Sheet1!A3,Table2[Product],Sheet1!B3) -> 13019.628 | F3: =COUNTIF(Table2[Category],Sheet1!A3) -> 46 | G3: =COUNTIFS(Table2[Category],Sheet1!A3,Table2[Product],Sheet1!B3) -> 10 | K3: Monitor 27" | L3: 13019.628
A4: Electronics | B4: Headphones | C4: =SUMIFS(Table2[Final Amount ($)],Table2[Category],Sheet1!A4,Table2[Product],Sheet1!B4) -> 2833.782 | F4: =COUNTIF(Table2[Category],Sheet1!A4) -> 46 | G4: =COUNTIFS(Table2[Category],Sheet1!A4,Table2[Product],Sheet1!B4) -> 10 | K4: Desk Chair | L4: 9359.688
A5: Electronics | B5: Wireless Mouse | C5: =SUMIFS(Table2[Final Amount ($)],Table2[Category],Sheet1!A5,Table2[Product],Sheet1!B5) -> 278.907 | F5: =COUNTIF(Table2[Category],Sheet1!A5) -> 46 | G5: =COUNTIFS(Table2[Category],Sheet1!A5,Table2[Product],Sheet1!B5) -> 3 | K5: Standing Desk | L5: 8799.824
A6: Electronics | B6: Keyboard | C6: =SUMIFS(Table2[Final Amount ($)],Table2[Category],Sheet1!A6,Table2[Product],Sheet1!B6) -> 1219.8475 | F6: =COUNTIF(Table2[Category],Sheet1!A6) -> 46 | G6: =COUNTIFS(Table2[Category],Sheet1!A6,Table2[Product],Sheet1!B6) -> 6 | K6: Bookshelf | L6: 3217.2855
A7: Electronics | B7: Laptop | C7: =SUMIFS(Table2[Final Amount ($)],Table2[Category],Sheet1!A7,Table2[Product],Sheet1!B7) -> 26639.704 | F7: =COUNTIF(Table2[Category],Sheet1!A7) -> 46 | G7: =COUNTIFS(Table2[Category],Sheet1!A7,Table2[Product],Sheet1!B7) -> 8 | K7: Headphones | L7: 2833.782
A8: Electronics | B8: USB-C Hub | C8: =SUMIFS(Table2[Final Amount ($)],Table2[Category],Sheet1!A8,Table2[Product],Sheet1!B8) -> 707.3585 | F8: =COUNTIF(Table2[Category],Sheet1!A8) -> 46 | G8: =COUNTIFS(Table2[Category],Sheet1!A8,Table2[Product],Sheet1!B8) -> 6 | K8: Keyboard | L8: 1219.8475
A9: Furniture | B9: Standing Desk | C9: =SUMIFS(Table2[Final Amount ($)],Table2[Category],Sheet1!A9,Table2[Product],Sheet1!B9) -> 8799.824 | F9: =COUNTIF(Table2[Category],Sheet1!A9) -> 32 | G9: =COUNTIFS(Table2[Category],Sheet1!A9,Table2[Product],Sheet1!B9) -> 8 | K9: Whiteboard | L9: 1031.828
K10: Desk Lamp | L10: 871.782
A11: Furniture | B11: Desk Lamp | C11: =SUMIFS(Table2[Final Amount ($)],Table2[Category],Sheet1!A11,Table2[Product],Sheet1!B11) -> 871.782 | F11: =COUNTIF(Table2[Category],Sheet1!A11) -> 32 | G11: =COUNTIFS(Table2[Category],Sheet1!A11,Table2[Product],Sheet1!B11) -> 8 | K11: USB-C Hub | L11: 707.3585
A12: Furniture | B12: Desk Chair | C12: =SUMIFS(Table2[Final Amount ($)],Table2[Category],Sheet1!A12,Table2[Product],Sheet1!B12) -> 9359.688 | F12: =COUNTIF(Table2[Category],Sheet1!A12) -> 32 | G12: =COUNTIFS(Table2[Category],Sheet1!A12,Table2[Product],Sheet1!B12) -> 10 | K12: Webcam HD | L12: 542.4225
A13: Furniture | B13: Bookshelf | C13: =SUMIFS(Table2[Final Amount ($)],Table2[Category],Sheet1!A13,Table2[Product],Sheet1!B13) -> 3217.2855 | F13: =COUNTIF(Table2[Category],Sheet1!A13) -> 32 | G13: =COUNTIFS(Table2[Category],Sheet1!A13,Table2[Product],Sheet1!B13) -> 6 | K13: Notebook Pack | L13: 308.5125
A14: Office Supplies | B14: Notebook Pack | C14: =SUMIFS(Table2[Final Amount ($)],Table2[Category],Sheet1!A14,Table2[Product],Sheet1!B14) -> 308.5125 | F14: =COUNTIF(Table2[Category],Sheet1!A14) -> 24 | G14: =COUNTIFS(Table2[Category],Sheet1!A14,Table2[Product],Sheet1!B14) -> 8 | K14: Printer Paper | L14: 303.6285
A15: Office Supplies | B15: Whiteboard | C15: =SUMIFS(Table2[Final Amount ($)],Table2[Category],Sheet1!A15,Table2[Product],Sheet1!B15) -> 1031.828 | F15: =COUNTIF(Table2[Category],Sheet1!A15) -> 24 | G15: =COUNTIFS(Table2[Category],Sheet1!A15,Table2[Product],Sheet1!B15) -> 7 | K15: Wireless Mouse | L15: 278.907
A16: Office Supplies | B16: Printer Paper | C16: =SUMIFS(Table2[Final Amount ($)],Table2[Category],Sheet1!A16,Table2[Product],Sheet1!B16) -> 303.6285 | F16: =COUNTIF(Table2[Category],Sheet1!A16) -> 24 | G16: =COUNTIFS(Table2[Category],Sheet1!A16,Table2[Product],Sheet1!B16) -> 4 | K16: Pen Set | L16: 92.1475
A17: Office Supplies | B17: Pen Set | C17: =SUMIFS(Table2[Final Amount ($)],Table2[Category],Sheet1!A17,Table2[Product],Sheet1!B17) -> 92.1475 | F17: =COUNTIF(Table2[Category],Sheet1!A17) -> 24 | G17: =COUNTIFS(Table2[Category],Sheet1!A17,Table2[Product],Sheet1!B17) -> 5 | K17: Grand Total | L17: 69226.345
D18: =COUNT(Table2[Quantity]) -> 102 | E18: =COUNTA(Table2[Category]) -> 102

Sheet SUM Functions
A1: 📌 SUM, SUMIF & SUMIFS — Adding Up Numbers with Conditions
A3: 🎯 USE CASE: "How much total revenue did we make? How much from Electronics only? How much from Electronics in NSW?"
A5: 🔧 SYNTAX REFERENCE
A6: Formula | B6: Syntax | E6: What It Does
A7: SUM | B7: =SUM(range) | E7: Adds all numbers in a range
A8: SUMIF | B8: =SUMIF(range, criteria, sum_range) | E8: Adds numbers that meet ONE condition
A9: SUMIFS | B9: =SUMIFS(sum_range, range1, criteria1, range2, criteria2, ...) | E9: Adds numbers that meet MULTIPLE conditions
A12: 📊 LIVE DEMO — Using Sales Data
A13: Question | D13: Formula | H13: Result
A14: Total revenue (all orders)? | D14: =SUM('Sales Data'!N4:N105) -> 69226.345 | H14: =SUM('Sales Data'!N4:N105) -> 69226.345
A15: Total revenue from Electronics? | D15: =SUMIF('Sales Data'!H4:H105,"Electronics",'Sales Data'!N4:N105) -> 45241.649 | H15: =SUMIF('Sales Data'!H4:H105,"Electronics",'Sales Data'!N4:N105) -> 45241.649
A16: Total revenue from Furniture? | D16: =SUMIF('Sales Data'!H4:H105,"Furniture",'Sales Data'!N4:N105) -> 22248.579 | H16: =SUMIF('Sales Data'!H4:H105,"Furniture",'Sales Data'!N4:N105) -> 22248.579
A17: Electronics revenue in NSW? | D17: =SUMIFS('Sales Data'!N4:N105,'Sales Data'!H4:H105,"Electronics",'Sales Data'!F4:F105,"NSW") -> 10199.694 | H17: =SUMIFS('Sales Data'!N4:N105,'Sales Data'!H4:H105,"Electronics",'Sales Data'!F4:F105,"NSW") -> 10199.694
A18: Revenue from Alice Morgan for Delivered orders? | D18: =SUMIFS('Sales Data'!N4:N105,'Sales Data'!P4:P105,"Alice Morgan",'Sales Data'!O4:O105,"Delivered") -> 6410.8895 | H18: =SUMIFS('Sales Data'!N4:N105,'Sales Data'!P4:P105,"Alice Morgan",'Sales Data'!O4:O105,"Delivered") -> 6410.8895
A21: ✏️ TRY IT YOURSELF
A22: Your Task | E22: Write Your Formula Here
A23: What is the total revenue from Office Supplies? | E23: =SUMIF('Sales Data'!H4:H105,"Office Supplies",'Sales Data'!N4:N105) -> 1736.1165
A24: What is the total revenue from Melbourne? | E24: =SUMIF('Sales Data'!E4:E105,"Melbourne",'Sales Data'!N4:N105) -> 16119.649
A25: What is the total revenue from VIC for Furniture? | E25: =SUMIFS('Sales Data'!N4:N105,'Sales Data'!F4:F105,"VIC",'Sales Data'!H4:H105,"Furniture") -> 8379.1795

Sheet COUNT Functions
A1: 📌 COUNT, COUNTA, COUNTIF & COUNTIFS — Counting with Precision
A3: 🎯 USE CASE: "How many orders do we have? How many are Delivered? How many Electronics orders from Sydney?"
A5: 🔧 SYNTAX REFERENCE
A6: Formula | B6: Syntax | E6: What It Does
A7: COUNT | B7: =COUNT(range) | E7: Counts cells with numbers
A8: COUNTA | B8: =COUNTA(range) | E8: Counts non-empty cells (text + numbers)
A9: COUNTIF | B9: =COUNTIF(range, criteria) | E9: Counts cells meeting ONE condition
A10: COUNTIFS | B10: =COUNTIFS(range1, criteria1, range2, criteria2, ...) | E10: Counts cells meeting MULTIPLE conditions
A11: COUNTBLANK | B11: =COUNTBLANK(range) | E11: Counts empty cells
A14: 📊 LIVE DEMO
A15: Question | D15: Formula | H15: Result | K15: Categories
A16: How many orders total? | D16: =COUNTA('Sales Data'!H4:H105) -> 102 | H16: =COUNTA('Sales Data'!A4:A105) -> 102 | K16: Electronics
A17: How many Delivered orders? | D17: =E25 -> 19 | H17: =COUNTIF('Sales Data'!O4:O105,"Delivered") -> 63
A18: How many Returned orders? | D18: =COUNTIF('Sales Data'!O4:O105,"Returned") -> 14 | H18: =COUNTIF('Sales Data'!O4:O105,"Returned") -> 14
A19: How many Electronics orders in NSW? | D19: =COUNTIFS('Sales Data'!H4:H105,"Electronics",'Sales Data'!F4:F105,"VIC") -> 11 | H19: =COUNTIFS('Sales Data'!H4:H105,"Electronics",'Sales Data'!F4:F105,"NSW") -> 11
A20: Orders by Bob Smith that are Shipped? | D20: =COUNTIFS('Sales Data'!P4:P105,"Bob Smith",'Sales Data'!O4:O105,"Shipped") -> 4 | H20: =COUNTIFS('Sales Data'!P4:P105,"Bob Smith",'Sales Data'!O4:O105,"Shipped") -> 4
A23: ✏️ TRY IT YOURSELF
A24: Your Task | E24: Write Your Formula Here
A25: How many orders were paid by PayPal? | E25: =COUNTIF('Sales Data'!Q4:Q106,"PayPal") -> 19
A26: How many Furniture orders are in VIC? | E26: =COUNTIFS('Sales Data'!H4:H105,"Furniture",'Sales Data'!F4:F105,"VIC") -> 8
A27: How many orders have a discount > 0? | E27: =COUNTA('Sales Data'!M4:M105) -> 102

Sheet AVERAGE MIN MAX
A1: 📌 AVERAGE, AVERAGEIF, MIN, MAX & LARGE/SMALL
A3: 🎯 USE CASE: "What is our average order value? What is the avg for Electronics? What was our biggest/smallest order?"
A5: 🔧 SYNTAX REFERENCE
A6: Formula | B6: Syntax | E6: What It Does
A7: AVERAGE | B7: =AVERAGE(range) | E7: Average of all numbers
A8: AVERAGEIF | B8: =AVERAGEIF(range, criteria, avg_range) | E8: Average with ONE condition
A9: AVERAGEIFS | B9: =AVERAGEIFS(avg_range, range1, criteria1, ...) | E9: Average with MULTIPLE conditions
A10: MIN | B10: =MIN(range) | E10: Smallest value
A11: MAX | B11: =MAX(range) | E11: Largest value
A12: LARGE | B12: =LARGE(range, k) | E12: k-th largest value
A13: SMALL | B13: =SMALL(range, k) | E13: k-th smallest value
A16: 📊 LIVE DEMO
A17: Question | D17: Formula | H17: Result
A18: Average order value? | D18: =AVERAGE('Sales Data'!N4:N105) -> 685.40936 | H18: =AVERAGE('Sales Data'!N4:N105) -> 685.40936
A19: Average for Electronics? | D19: =AVERAGEIF('Sales Data'!H4:H105,"Electronics",'Sales Data'!N4:N105) -> 983.51412 | H19: =AVERAGEIF('Sales Data'!H4:H105,"Electronics",'Sales Data'!N4:N105) -> 983.51412
A20: Avg for Delivered orders in Sydney? | D20: =AVERAGEIFS('Sales Data'!N4:N105,'Sales Data'!O4:O105,"Delivered",'Sales Data'!E4:E105,"Sydney") -> 409.08057 | H20: =AVERAGEIFS('Sales Data'!N4:N105,'Sales Data'!O4:O105,"Delivered",'Sales Data'!E4:E105,"Sydney") -> 409.08057
A21: Largest single order? | D21: =MAX('Sales Data'!N4:N105) -> 4499.95 | H21: =MAX('Sales Data'!N4:N105) -> 4499.95
A22: Smallest single order? | D22: =MIN('Sales Data'!N4:N105) -> 8.091 | H22: =MIN('Sales Data'!N4:N105) -> 8.091
A23: 2nd largest order? | D23: =LARGE('Sales Data'!N4:N105,2) -> 4049.955 | H23: =LARGE('Sales Data'!N4:N105,2) -> 4049.955
A24: 3rd smallest order? | D24: =SMALL('Sales Data'!N4:N105,3) -> 12.99 | H24: =SMALL('Sales Data'!N4:N105,3) -> 12.99
A27: ✏️ TRY IT YOURSELF
A28: Your Task | E28: Write Your Formula Here
A29: Average order value for Furniture? | E29: =AVERAGEIF('Sales Data'!H4:H105,"Furniture", 'Sales Data'!N4:N105) -> 717.69611
A30: What is the top 3rd highest order? | E30: =LARGE('Sales Data'!N4:N105,3) -> 3824.9575
A31: Average for Bob Smith's delivered orders? | E31: =AVERAGEIFS('Sales Data'!N4:N105,'Sales Data'!O4:O105,"Delivered",'Sales Data'!P4:P105,"Bob Smith") -> 855.60509

Sheet IF Functions
A1: 📌 IF, Nested IF, IFS, AND & OR — Making Decisions in Excel
J2: {=IF('Sales Data'!J4:J105>3, "Bulk","Single")} -> Bulk | K2: {=_xlfn.IFS('Sales Data'!J3 >= 4, "Large", 'Sales Data'!J3 >= 2, "Medium",'Sales Data'!J3 < 2,"Small")} -> Large | L2: {=IF(AND('Sales Data'!O4:O105="Returned",'Sales Data'!N4:N104>500),"Yes","No")} -> No
A3: 🎯 USE CASE: "Label orders as High/Low value, categorize discounts, flag orders that need attention" | J3: Bulk | K3: {=_xlfn.IFS('Sales Data'!J4 >= 4, "Large", 'Sales Data'!J4 >= 2, "Medium",'Sales Data'!J4 < 2,"Small")} -> Large | L3: {=IF(AND('Sales Data'!O5:O106="Returned",'Sales Data'!N5:N105>500),"Yes","No")} -> No
J4: Bulk | K4: {=_xlfn.IFS('Sales Data'!J5 >= 4, "Large", 'Sales Data'!J5 >= 2, "Medium",'Sales Data'!J5 < 2,"Small")} -> Large | L4: {=IF(AND('Sales Data'!O6:O107="Returned",'Sales Data'!N6:N106>500),"Yes","No")} -> No
A5: 🔧 SYNTAX REFERENCE | J5: Bulk | K5: {=_xlfn.IFS('Sales Data'!J6 >= 4, "Large", 'Sales Data'!J6 >= 2, "Medium",'Sales Data'!J6 < 2,"Small")} -> Large | L5: {=IF(AND('Sales Data'!O7:O108="Returned",'Sales Data'!N7:N107>500),"Yes","No")} -> No
A6: Formula | B6: Syntax | E6: What It Does | J6: Bulk | K6: {=_xlfn.IFS('Sales Data'!J7 >= 4, "Large", 'Sales Data'!J7 >= 2, "Medium",'Sales Data'!J7 < 2,"Small")} -> Large | L6: {=IF(AND('Sales Data'!O8:O109="Returned",'Sales Data'!N8:N108>500),"Yes","No")} -> No
A7: IF | B7: =IF(condition, true_value, false_value) | E7: Returns one value if TRUE, another if FALSE | J7: Single | K7: {=_xlfn.IFS('Sales Data'!J8 >= 4, "Large", 'Sales Data'!J8 >= 2, "Medium",'Sales Data'!J8 < 2,"Small")} -> Large | L7: {=IF(AND('Sales Data'!O9:O110="Returned",'Sales Data'!N9:N109>500),"Yes","No")} -> No
A8: Nested IF | B8: =IF(cond1, VAL1, IF(cond2, VAL2, VAL3)) | E8: Multiple conditions checked in order | J8: Bulk | K8: {=_xlfn.IFS('Sales Data'!J9 >= 4, "Large", 'Sales Data'!J9 >= 2, "Medium",'Sales Data'!J9 < 2,"Small")} -> Medium | L8: {=IF(AND('Sales Data'!O10:O111="Returned",'Sales Data'!N10:N110>500),"Yes","No")} -> No
A9: IFS | B9: =ifs(cond1, VAL1, cond2, VAL2, ...) | E9: Cleaner way to check multiple conditions | J9: Single | K9: {=_xlfn.IFS('Sales Data'!J10 >= 4, "Large", 'Sales Data'!J10 >= 2, "Medium",'Sales Data'!J10 < 2,"Small")} -> Large | L9: {=IF(AND('Sales Data'!O11:O112="Returned",'Sales Data'!N11:N111>500),"Yes","No")} -> No
A10: AND | B10: =AND(cond1, cond2, ...) | E10: TRUE only if ALL conditions are TRUE | J10: Single | K10: {=_xlfn.IFS('Sales Data'!J11 >= 4, "Large", 'Sales Data'!J11 >= 2, "Medium",'Sales Data'!J11 < 2,"Small")} -> Medium | L10: {=IF(AND('Sales Data'!O12:O113="Returned",'Sales Data'!N12:N112>500),"Yes","No")} -> No
A11: OR | B11: =OR(cond1, cond2, ...) | E11: TRUE if ANY condition is TRUE | J11: Bulk | K11: {=_xlfn.IFS('Sales Data'!J12 >= 4, "Large", 'Sales Data'!J12 >= 2, "Medium",'Sales Data'!J12 < 2,"Small")} -> Medium | L11: {=IF(AND('Sales Data'!O13:O114="Returned",'Sales Data'!N13:N113>500),"Yes","No")} -> No
J12: Bulk | K12: {=_xlfn.IFS('Sales Data'!J13 >= 4, "Large", 'Sales Data'!J13 >= 2, "Medium",'Sales Data'!J13 < 2,"Small")} -> Large | L12: {=IF(AND('Sales Data'!O14:O115="Returned",'Sales Data'!N14:N114>500),"Yes","No")} -> No
J13: Bulk | K13: {=_xlfn.IFS('Sales Data'!J14 >= 4, "Large", 'Sales Data'!J14 >= 2, "Medium",'Sales Data'!J14 < 2,"Small")} -> Large | L13: {=IF(AND('Sales Data'!O15:O116="Returned",'Sales Data'!N15:N115>500),"Yes","No")} -> No
A14: 📊 LIVE DEMO — Classifying Orders | J14: Bulk | K14: {=_xlfn.IFS('Sales Data'!J15 >= 4, "Large", 'Sales Data'!J15 >= 2, "Medium",'Sales Data'!J15 < 2,"Small")} -> Large | L14: {=IF(AND('Sales Data'!O16:O117="Returned",'Sales Data'!N16:N116>500),"Yes","No")} -> No
A15: Order ID | B15: Amount ($) | C15: Status | D15: Discount % | E15: IF: High/Low? | F15: IFS: Tier | G15: Needs Follow-up? | J15: Bulk | K15: {=_xlfn.IFS('Sales Data'!J16 >= 4, "Large", 'Sales Data'!J16 >= 2, "Medium",'Sales Data'!J16 < 2,"Small")} -> Large | L15: {=IF(AND('Sales Data'!O17:O118="Returned",'Sales Data'!N17:N117>500),"Yes","No")} -> No
A16: ORD-1001 | B16: 2500 | C16: Delivered | D16: 0 | E16: =IF(B16>500,"High Value","Low Value") -> High Value | F16: =_xlfn.IFS(B16>=2000,"Premium",B16>=500,"Standard",B16<500,"Budget") -> Premium | G16: =IF(OR(C16="Returned",AND(C16="Processing",D16>0.1)),"Yes","No") -> No | I16: =IF(OR(C16="Returned",AND(C16="Processing",D16>0.1)),"Y","N") -> N | J16: Bulk | K16: {=_xlfn.IFS('Sales Data'!J17 >= 4, "Large", 'Sales Data'!J17 >= 2, "Medium",'Sales Data'!J17 < 2,"Small")} -> Large | L16: {=IF(AND('Sales Data'!O18:O119="Returned",'Sales Data'!N18:N118>500),"Yes","No")} -> No
A17: ORD-1005 | B17: 150 | C17: Processing | D17: 0.1 | E17: =IF(B17>500,"High Value","Low Value") -> Low Value | F17: =_xlfn.IFS(B17>=2000,"Premium",B17>=500,"Standard",B17<500,"Budget") -> Budget | G17: =IF(OR(C17="Returned",AND(C17="Processing",D17>0.1)),"Yes","No") -> No | I17: =IF(OR(C17="Returned",AND(C17="Processing",D17>0.1)),"Y","N") -> N | J17: Bulk | K17: {=_xlfn.IFS('Sales Data'!J18 >= 4, "Large", 'Sales Data'!J18 >= 2, "Medium",'Sales Data'!J18 < 2,"Small")} -> Large | L17: {=IF(AND('Sales Data'!O19:O120="Returned",'Sales Data'!N19:N119>500),"Yes","No")} -> No
A18: ORD-1012 | B18: 800 | C18: Returned | D18: 0.05 | E18: =IF(B18>500,"High Value","Low Value") -> High Value | F18: =_xlfn.IFS(B18>=2000,"Premium",B18>=500,"Standard",B18<500,"Budget") -> Standard | G18: =IF(OR(C18="Returned",AND(C18="Processing",D18>0.1)),"Yes","No") -> Yes | I18: =IF(OR(C18="Returned",AND(C18="Processing",D18>0.1)),"Y","N") -> Y | J18: Bulk | K18: {=_xlfn.IFS('Sales Data'!J19 >= 4, "Large", 'Sales Data'!J19 >= 2, "Medium",'Sales Data'!J19 < 2,"Small")} -> Large | L18: {=IF(AND('Sales Data'!O20:O121="Returned",'Sales Data'!N20:N120>500),"Yes","No")} -> No
A19: ORD-1020 | B19: 45 | C19: Delivered | D19: 0.2 | E19: =IF(B19>500,"High Value","Low Value") -> Low Value | F19: =_xlfn.IFS(B19>=2000,"Premium",B19>=500,"Standard",B19<500,"Budget") -> Budget | G19: =IF(OR(C19="Returned",AND(C19="Processing",D19>0.1)),"Yes","No") -> No | I19: =IF(OR(C19="Returned",AND(C19="Processing",D19>0.1)),"Y","N") -> N | J19: Bulk | K19: {=_xlfn.IFS('Sales Data'!J20 >= 4, "Large", 'Sales Data'!J20 >= 2, "Medium",'Sales Data'!J20 < 2,"Small")} -> Large | L19: {=IF(AND('Sales Data'!O21:O122="Returned",'Sales Data'!N21:N121>500),"Yes","No")} -> No
A20: ORD-1033 | B20: 3500 | C20: Shipped | D20: 0 | E20: =IF(B20>500,"High Value","Low Value") -> High Value | F20: =_xlfn.IFS(B20>=2000,"Premium",B20>=500,"Standard",B20<500,"Budget") -> Premium | G20: =IF(OR(C20="Returned",AND(C20="Processing",D20>0.1)),"Yes","No") -> No | I20: =IF(OR(C20="Returned",AND(C20="Processing",D20>0.1)),"Y","N") -> N | J20: Bulk | K20: {=_xlfn.IFS('Sales Data'!J21 >= 4, "Large", 'Sales Data'!J21 >= 2, "Medium",'Sales Data'!J21 < 2,"Small")} -> Large | L20: {=IF(AND('Sales Data'!O22:O123="Returned",'Sales Data'!N22:N122>500),"Yes","No")} -> No
A21: ORD-1045 | B21: 500 | C21: Returned | D21: 0.15 | E21: =IF(B21>500,"High Value","Low Value") -> Low Value | F21: =_xlfn.IFS(B21>=2000,"Premium",B21>=500,"Standard",B21<500,"Budget") -> Standard | G21: =IF(OR(C21="Returned",AND(C21="Processing",D21>0.1)),"Yes","No") -> Yes | I21: =IF(OR(C21="Returned",AND(C21="Processing",D21>0.1)),"Y","N") -> Y | J21: Bulk | K21: {=_xlfn.IFS('Sales Data'!J22 >= 4, "Large", 'Sales Data'!J22 >= 2, "Medium",'Sales Data'!J22 < 2,"Small")} -> Large | L21: {=IF(AND('Sales Data'!O23:O124="Returned",'Sales Data'!N23:N123>500),"Yes","No")} -> No
A22: ORD-1050 | B22: 1200 | C22: Delivered | D22: 0 | E22: =IF(B22>500,"High Value","Low Value") -> High Value | F22: =_xlfn.IFS(B22>=2000,"Premium",B22>=500,"Standard",B22<500,"Budget") -> Standard | G22: =IF(OR(C22="Returned",AND(C22="Processing",D22>0.1)),"Yes","No") -> No | I22: =IF(OR(C22="Returned",AND(C22="Processing",D22>0.1)),"Y","N") -> N | J22: Bulk | K22: {=_xlfn.IFS('Sales Data'!J23 >= 4, "Large", 'Sales Data'!J23 >= 2, "Medium",'Sales Data'!J23 < 2,"Small")} -> Large | L22: {=IF(AND('Sales Data'!O24:O125="Returned",'Sales Data'!N24:N124>500),"Yes","No")} -> No
A23: ORD-1067 | B23: 75 | C23: Processing | D23: 0.2 | E23: =IF(B23>500,"High Value","Low Value") -> Low Value | F23: =_xlfn.IFS(B23>=2000,"Premium",B23>=500,"Standard",B23<500,"Budget") -> Budget | G23: =IF(OR(C23="Returned",AND(C23="Processing",D23>0.1)),"Yes","No") -> Yes | I23: =IF(OR(C23="Returned",AND(C23="Processing",D23>0.1)),"Y","N") -> Y | J23: Bulk | K23: {=_xlfn.IFS('Sales Data'!J24 >= 4, "Large", 'Sales Data'!J24 >= 2, "Medium",'Sales Data'!J24 < 2,"Small")} -> Large | L23: {=IF(AND('Sales Data'!O25:O126="Returned",'Sales Data'!N25:N125>500),"Yes","No")} -> No
J24: Single | K24: {=_xlfn.IFS('Sales Data'!J25 >= 4, "Large", 'Sales Data'!J25 >= 2, "Medium",'Sales Data'!J25 < 2,"Small")} -> Large | L24: {=IF(AND('Sales Data'!O26:O127="Returned",'Sales Data'!N26:N126>500),"Yes","No")} -> No
J25: Single | K25: {=_xlfn.IFS('Sales Data'!J26 >= 4, "Large", 'Sales Data'!J26 >= 2, "Medium",'Sales Data'!J26 < 2,"Small")} -> Medium | L25: {=IF(AND('Sales Data'!O27:O128="Returned",'Sales Data'!N27:N127>500),"Yes","No")} -> No
A26: 💡 FORMULA BREAKDOWN | J26: Bulk | K26: {=_xlfn.IFS('Sales Data'!J27 >= 4, "Large", 'Sales Data'!J27 >= 2, "Medium",'Sales Data'!J27 < 2,"Small")} -> Medium | L26: {=IF(AND('Sales Data'!O28:O129="Returned",'Sales Data'!N28:N128>500),"Yes","No")} -> No
A27: Column E: =IF(B>500, "High Value", "Low Value") → Simple yes/no decision | J27: Single | K27: {=_xlfn.IFS('Sales Data'!J28 >= 4, "Large", 'Sales Data'!J28 >= 2, "Medium",'Sales Data'!J28 < 2,"Small")} -> Large | L27: {=IF(AND('Sales Data'!O29:O130="Returned",'Sales Data'!N29:N129>500),"Yes","No")} -> No
A28: Column F: =IFS(B>=2000, "Premium", B>=500, "Standard", B<500, "Budget") → Multi-tier classification | J28: Single | K28: {=_xlfn.IFS('Sales Data'!J29 >= 4, "Large", 'Sales Data'!J29 >= 2, "Medium",'Sales Data'!J29 < 2,"Small")} -> Medium | L28: {=IF(AND('Sales Data'!O30:O131="Returned",'Sales Data'!N30:N130>500),"Yes","No")} -> No
A29: Column G: =IF(OR(Returned, AND(Processing, Discount>10%)), "Yes", "No") → Complex business rule | J29: Bulk | K29: {=_xlfn.IFS('Sales Data'!J30 >= 4, "Large", 'Sales Data'!J30 >= 2, "Medium",'Sales Data'!J30 < 2,"Small")} -> Medium | L29: {=IF(AND('Sales Data'!O31:O132="Returned",'Sales Data'!N31:N131>500),"Yes","No")} -> No
J30: Bulk | K30: {=_xlfn.IFS('Sales Data'!J31 >= 4, "Large", 'Sales Data'!J31 >= 2, "Medium",'Sales Data'!J31 < 2,"Small")} -> Large | L30: {=IF(AND('Sales Data'!O32:O133="Returned",'Sales Data'!N32:N132>500),"Yes","No")} -> No
J31: Single | K31: {=_xlfn.IFS('Sales Data'!J32 >= 4, "Large", 'Sales Data'!J32 >= 2, "Medium",'Sales Data'!J32 < 2,"Small")} -> Large | L31: {=IF(AND('Sales Data'!O33:O134="Returned",'Sales Data'!N33:N133>500),"Yes","No")} -> No
A32: ✏️ TRY IT YOURSELF | J32: Single | K32: {=_xlfn.IFS('Sales Data'!J33 >= 4, "Large", 'Sales Data'!J33 >= 2, "Medium",'Sales Data'!J33 < 2,"Small")} -> Medium | L32: {=IF(AND('Sales Data'!O34:O135="Returned",'Sales Data'!N34:N134>500),"Yes","No")} -> No
A33: Your Task | J33: Bulk | K33: {=_xlfn.IFS('Sales Data'!J34 >= 4, "Large", 'Sales Data'!J34 >= 2, "Medium",'Sales Data'!J34 < 2,"Small")} -> Medium | L33: {=IF(AND('Sales Data'!O35:O136="Returned",'Sales Data'!N35:N135>500),"Yes","No")} -> No
A34: If quantity > 3, label "Bulk" else "Single" | E34: Start at J2 | J34: Single | K34: {=_xlfn.IFS('Sales Data'!J35 >= 4, "Large", 'Sales Data'!J35 >= 2, "Medium",'Sales Data'!J35 < 2,"Small")} -> Large | L34: {=IF(AND('Sales Data'!O36:O137="Returned",'Sales Data'!N36:N136>500),"Yes","No")} -> No
A35: Create a 3-tier label: qty>=4 "Large", qty>=2 "Medium", else "Small" | E35: Start at K2 | J35: Bulk | K35: {=_xlfn.IFS('Sales Data'!J36 >= 4, "Large", 'Sales Data'!J36 >= 2, "Medium",'Sales Data'!J36 < 2,"Small")} -> Medium | L35: {=IF(AND('Sales Data'!O37:O138="Returned",'Sales Data'!N37:N137>500),"Yes","No")} -> No
A36: Flag if Returned AND amount > $500 | E36: Start at L2 | J36: Single | K36: {=_xlfn.IFS('Sales Data'!J37 >= 4, "Large", 'Sales Data'!J37 >= 2, "Medium",'Sales Data'!J37 < 2,"Small")} -> Large | L36: {=IF(AND('Sales Data'!O38:O139="Returned",'Sales Data'!N38:N138>500),"Yes","No")} -> No
J37: Single | K37: {=_xlfn.IFS('Sales Data'!J38 >= 4, "Large", 'Sales Data'!J38 >= 2, "Medium",'Sales Data'!J38 < 2,"Small")} -> Small | L37: {=IF(AND('Sales Data'!O39:O140="Returned",'Sales Data'!N39:N139>500),"Yes","No")} -> No
J38: Single | K38: {=_xlfn.IFS('Sales Data'!J39 >= 4, "Large", 'Sales Data'!J39 >= 2, "Medium",'Sales Data'!J39 < 2,"Small")} -> Small | L38: {=IF(AND('Sales Data'!O40:O141="Returned",'Sales Data'!N40:N140>500),"Yes","No")} -> No
J39: Single | K39: {=_xlfn.IFS('Sales Data'!J40 >= 4, "Large", 'Sales Data'!J40 >= 2, "Medium",'Sales Data'!J40 < 2,"Small")} -> Small | L39: {=IF(AND('Sales Data'!O41:O142="Returned",'Sales Data'!N41:N141>500),"Yes","No")} -> No
J40: Single | K40: {=_xlfn.IFS('Sales Data'!J41 >= 4, "Large", 'Sales Data'!J41 >= 2, "Medium",'Sales Data'!J41 < 2,"Small")} -> Small | L40: {=IF(AND('Sales Data'!O42:O143="Returned",'Sales Data'!N42:N142>500),"Yes","No")} -> No
...

Sheet Campaign_Data
A1: Campaign_ID | B1: Campaign_Name | C1: Channel | D1: Campaign_Type | E1: Quarter | F1: Start_Date | G1: End_Date | H1: Region | I1: Budget | J1: Spend | K1: Impressions | L1: Clicks | M1: Conversions | N1: Revenue | O1: Target_CPA | P1: Target_ROAS
A2: C001 | B2: Spring_Launch | C2: Facebook | D2: Brand | E2: Q1 | F2: 45306 | G2: 45350 | H2: National | I2: 15000 | J2: 14250 | K2: 850000 | L2: 12750 | M2: 382 | N2: 38200 | O2: 45 | P2: 2.5
A3: C002 | B3: Spring_Launch | C3: Google | D3: Search | E3: Q1 | F3: 45306 | G3: 45350 | H3: National | I3: 20000 | J3: 19800 | K3: 450000 | L3: 18000 | M3: 540 | N3: 64800 | O3: 40 | P3: 3
A4: C003 | B4: Easter_Promo | C4: Instagram | D4: Promo | E4: Q1 | F4: 45371 | G4: 45387 | H4: South | I4: 8000 | J4: 7650 | K4: 320000 | L4: 6400 | M4: 192 | N4: 19200 | O4: 50 | P4: 2
A5: C004 | B5: Q1_Email_Blast | C5: Email | D5: Promo | E5: Q1 | F5: 45323 | G5: 45350 | H5: National | I5: 3000 | J5: 2850 | K5: 125000 | L5: 8750 | M5: 263 | N5: 31560 | O5: 12 | P5: 10
A6: C005 | B6: Winter_Clearance | C6: Facebook | D6: Promo | E6: Q1 | F6: 45296 | G6: 45322 | H6: North | I6: 12000 | J6: 11400 | K6: 680000 | L6: 10200 | M6: 306 | N6: 27540 | O6: 42 | P6: 2.2
A7: C006 | B7: Brand_Awareness_Q1 | C7: LinkedIn | D7: Brand | E7: Q1 | F7: 45301 | G7: 45382 | H7: West | I7: 18000 | J7: 17100 | K7: 240000 | L7: 4800 | M7: 144 | N7: 21600 | O7: 130 | P7: 1.2
A8: C007 | B8: Summer_Sale_2024 | C8: Facebook | D8: Promo | E8: Q2 | F8: 45444 | G8: 45473 | H8: National | I8: 25000 | J8: 24500 | K8: 1200000 | L8: 24000 | M8: 720 | N8: 86400 | O8: 35 | P8: 3.5
A9: C008 | B9: Summer_Sale_2024 | C9: Google | D9: Search | E9: Q2 | F9: 45444 | G9: 45473 | H9: National | I9: 30000 | J9: 28900 | K9: 520000 | L9: 26000 | M9: 845 | N9: 101400 | O9: 38 | P9: 3.2
A10: C009 | B10: July_Clearance | C10: LinkedIn | D10: Promo | E10: Q2 | F10: 45483 | G10: 45504 | H10: West | I10: 12000 | J10: 11400 | K10: 180000 | L10: 3600 | M10: 108 | N10: 16200 | O10: 120 | P10: 1.5
A11: C010 | B11: Mother_Day_Special | C11: Instagram | D11: Promo | E11: Q2 | F11: 45413 | G11: 45424 | H11: East | I11: 9500 | J11: 9025 | K11: 420000 | L11: 8400 | M11: 252 | N11: 30240 | O11: 40 | P11: 3.2
A12: C011 | B12: Memorial_Day | C12: TikTok | D12: Brand | E12: Q2 | F12: 45432 | G12: 45439 | H12: National | I12: 15000 | J12: 14250 | K12: 780000 | L12: 23400 | M12: 702 | N12: 42120 | O12: 22 | P12: 2.8
A13: C012 | B13: Q2_Retargeting | C13: Google | D13: Search | E13: Q2 | F13: 45397 | G13: 45473 | H13: National | I13: 22000 | J13: 21120 | K13: 380000 | L13: 19000 | M13: 627 | N13: 75240 | O13: 36 | P13: 3.4
... A25: C024 | B25: Holiday_Email_Series | C25: Email | D25: Promo | E25: Q4 | F25: 45611 | G25: 45651 | H25: National | I25: 5500 | J25: 5225 | K25: 220000 | L25: 15400 | M25: 462 | N25: 60060 | O25: 12.5 | P25: 10.5

Sheet VLOOKUP XLOOKUP
A1: 📌 VLOOKUP & XLOOKUP — Looking Up Data Like a Pro
A3: 🎯 USE CASE: "I have a product name — give me its price. I have an Order ID — give me the customer. Pull data from a lookup table."
A5: 🔧 SYNTAX REFERENCE
A6: Formula | B6: Syntax | E6: What It Does
A7: VLOOKUP | B7: =VLOOKUP(lookup_value, table, col_index, FALSE()) | E7: Looks up a value & returns from a specific column
A8: XLOOKUP | B8: =xlookup(lookup, lookup_range, return_range, [not_found]) | E8: Modern replacement — more flexible
A10: 📋 PRODUCT LOOKUP TABLE
A11: Product | B11: Category | C11: Unit Price ($) | D11: Stock Level | E11: Reorder Point | H11: Product | I11: Category | J11: Unit Price ($) | K11: Unit Price2 ($) | N11: Product | O11: Category | P11: Unit Price ($)
A12: Bookshelf | B12: Furniture | C12: 149.99 | D12: 25 | E12: 10 | F12: =IF(D12=E12,"Y","N") -> N | H12: =HLOOKUP(H$11,$A$11:$E$26,3,0) -> Desk Chair | I12: =VLOOKUP(H12,A11:E26,2) -> Furniture | J12: 10 | K12: =VLOOKUP(H12,N11:P14,3) -> 30 | L12: =IF(J12=K12,"Y","N") -> N | N12: Desk Chair | O12: Furniture | P12: 30
A13: Desk Chair | B13: Furniture | C13: 299.99 | D13: 15 | E13: 5 | F13: =IF(D13=E13,"Y","N") -> N | H13: =HLOOKUP(H$11,$A$11:$E$26,3,0) -> Desk Chair | I13: =_xlfn.XLOOKUP(H13,Table2[Product],Table2[City]) -> Melbourne
A14: Desk Lamp | B14: Furniture | C14: 39.99 | D14: 50 | E14: 20 | F14: =IF(D14=E14,"Y","N") -> N | H14: =HLOOKUP(H$11,$A$11:$E$26,3,0) -> Desk Chair
A15: Headphones | B15: Electronics | C15: 129.99 | D15: 40 | E15: 15 | F15: =IF(D15=E15,"Y","N") -> N
A16: Keyboard | B16: Electronics | C16: 79.99 | D16: 60 | E16: 25 | F16: =IF(D16=E16,"Y","N") -> N
A17: Laptop | B17: Electronics | C17: 899.99 | D17: 20 | E17: 8 | F17: =IF(D17=E17,"Y","N") -> N
A18: Monitor 27" | B18: Electronics | C18: 349.99 | D18: 30 | E18: 10 | F18: =IF(D18=E18,"Y","N") -> N
A19: Notebook Pack | B19: Office Supplies | C19: 12.99 | D19: 200 | E19: 50 | F19: =IF(D19=E19,"Y","N") -> N
A20: Pen Set | B20: Office Supplies | C20: 8.99 | D20: 150 | E20: 40 | F20: =IF(D20=E20,"Y","N") -> N
A21: Printer Paper | B21: Office Supplies | C21: 24.99 | D21: 100 | E21: 30 | F21: =IF(D21=E21,"Y","N") -> N
A22: Standing Desk | B22: Furniture | C22: 499.99 | D22: 10 | E22: 3 | F22: =IF(D22=E22,"Y","N") -> N
A23: USB-C Hub | B23: Electronics | C23: 49.99 | D23: 80 | E23: 30 | F23: =IF(D23=E23,"Y","N") -> N
A24: Webcam HD | B24: Electronics | C24: 69.99 | D24: 45 | E24: 15 | F24: =IF(D24=E24,"Y","N") -> N
A25: Whiteboard | B25: Office Supplies | C25: 59.99 | D25: 35 | E25: 10 | F25: =IF(D25=E25,"Y","N") -> N
A26: Wireless Mouse | B26: Electronics | C26: 29.99 | D26: 100 | E26: 40 | F26: =IF(D26=E26,"Y","N") -> N
A29: 📊 LIVE DEMO
A30: Search Product: | B30: Laptop | C30: Standing Desk | D30: Nintendo Switch
A32: Question | D32: Formula | H32: Result
A33: What is the price? (VLOOKUP) | D33: =VLOOKUP(B30,A12:E26,3,FALSE()) -> 899.99 | H33: =VLOOKUP(B30,A12:E26,3,FALSE()) -> 899.99
A34: What category? (VLOOKUP) | D34: =VLOOKUP(B30,A12:E26,2,FALSE()) -> Electronics | H34: =VLOOKUP(B30,A12:E26,2,FALSE()) -> Electronics
A35: Stock level? (XLOOKUP) | D35: =_xlfn.XLOOKUP(B30,A12:A26,D12:D26,"Not Found") -> 20 | H35: =_xlfn.XLOOKUP(B30,A12:A26,D12:D26,"Not Found") -> 20
A36: Reorder point? (XLOOKUP) | D36: =_xlfn.XLOOKUP(B30,A12:A26,E12:E26,"Not Found") -> 8 | H36: =_xlfn.XLOOKUP(B30,A12:A26,E12:E26,"Not Found") -> 8
A38: 💡 Change the product name in B30 to "Monitor 27\"" or "Pen Set" and watch all results update instantly!
A40: ⚡ VLOOKUP vs XLOOKUP — Why XLOOKUP Wins
A41: Feature | C41: VLOOKUP | F41: XLOOKUP
A42: Look left? | C42: ❌ No — only looks right | F42: ✅ Yes — any direction
A43: Default match | C43: ⚠️ Approximate (must add FALSE) | F43: ✅ Exact match by default
A44: Not found handling | C44: ❌ Returns #N/A error | F44: ✅ Custom "not found" message
A45: Column reference | C45: ❌ Uses column number (fragile) | F45: ✅ Uses column range (robust)
A48: ✏️ TRY IT YOURSELF
A49: Your Task | E49: Write Your Formula Here
A50: Look up the price of "Webcam HD" using VLOOKUP | E50: =VLOOKUP("WebCam HD", A2:E26,3,FALSE()) -> 69.99
...

Sheet Sheet2
A1: Campaign_ID | B1: Campaign_Name | C1: Channel | D1: Campaign_Type | E1: Quarter | F1: Start_Date | G1: End_Date | H1: Region | I1: Budget | J1: Spend | K1: Impressions | L1: Clicks | M1: Conversions | N1: Revenue | O1: Target_CPA | P1: Target_ROAS
A2: C001 | B2: Spring_Launch | C2: Facebook | D2: Brand | E2: Q1 | F2: 45306 | G2: 45350 | H2: National | I2: 15000 | J2: 14250 | K2: 850000 | L2: 12750 | M2: 382 | N2: 38200 | O2: 45 | P2: 2.5
A3: C002 | B3: Spring_Launch | C3: Google | D3: Search | E3: Q1 | F3: 45306 | G3: 45350 | H3: National | I3: 20000 | J3: 19800 | K3: 450000 | L3: 18000 | M3: 540 | N3: 64800 | O3: 40 | P3: 3
A4: C003 | B4: Easter_Promo | C4: Instagram | D4: Promo | E4: Q1 | F4: 45371 | G4: 45387 | H4: South | I4: 8000 | J4: 7650 | K4: 320000 | L4: 6400 | M4: 192 | N4: 19200 | O4: 50 | P4: 2
A5: C004 | B5: Q1_Email_Blast | C5: Email | D5: Promo | E5: Q1 | F5: 45323 | G5: 45350 | H5: National | I5: 3000 | J5: 2850 | K5: 125000 | L5: 8750 | M5: 263 | N5: 31560 | O5: 12 | P5: 10
A6: C005 | B6: Winter_Clearance | C6: Facebook | D6: Promo | E6: Q1 | F6: 45296 | G6: 45322 | H6: North | I6: 12000 | J6: 11400 | K6: 680000 | L6: 10200 | M6: 306 | N6: 27540 | O6: 42 | P6: 2.2
A7: C006 | B7: Brand_Awareness_Q1 | C7: LinkedIn | D7: Brand | E7: Q1 | F7: 45301 | G7: 45382 | H7: West | I7: 18000 | J7: 17100 | K7: 240000 | L7: 4800 | M7: 144 | N7: 21600 | O7: 130 | P7: 1.2
A8: C007 | B8: Summer_Sale_2024 | C8: Facebook | D8: Promo | E8: Q2 | F8: 45444 | G8: 45473 | H8: National | I8: 25000 | J8: 24500 | K8: 1200000 | L8: 24000 | M8: 720 | N8: 86400 | O8: 35 | P8: 3.5
A9: C008 | B9: Summer_Sale_2024 | C9: Google | D9: Search | E9: Q2 | F9: 45444 | G9: 45473 | H9: National | I9: 30000 | J9: 28900 | K9: 520000 | L9: 26000 | M9: 845 | N9: 101400 | O9: 38 | P9: 3.2
A10: C009 | B10: July_Clearance | C10: LinkedIn | D10: Promo | E10: Q2 | F10: 45483 | G10: 45504 | H10: West | I10: 12000 | J10: 11400 | K10: 180000 | L10: 3600 | M10: 108 | N10: 16200 | O10: 120 | P10: 1.5
A11: C010 | B11: Mother_Day_Special | C11: Instagram | D11: Promo | E11: Q2 | F11: 45413 | G11: 45424 | H11: East | I11: 9500 | J11: 9025 | K11: 420000 | L11: 8400 | M11: 252 | N11: 30240 | O11: 40 | P11: 3.2
A12: C011 | B12: Memorial_Day | C12: TikTok | D12: Brand | E12: Q2 | F12: 45432 | G12: 45439 | H12: National | I12: 15000 | J12: 14250 | K12: 780000 | L12: 23400 | M12: 702 | N12: 42120 | O12: 22 | P12: 2.8
A13: C012 | B13: Q2_Retargeting | C13: Google | D13: Search | E13: Q2 | F13: 45397 | G13: 45473 | H13: National | I13: 22000 | J13: 21120 | K13: 380000 | L13: 19000 | M13: 627 | N13: 75240 | O13: 36 | P13: 3.4
... A25: C024 | B25: Holiday_Email_Series | C25: Email | D25: Promo | E25: Q4 | F25: 45611 | G25: 45651 | H25: National | I25: 5500 | J25: 5225 | K25: 220000 | L25: 15400 | M25: 462 | N25: 60060 | O25: 12.5 | P25: 10.5

Sheet TEXT Functions
A1: 📌 TEXT Functions — Cleaning & Transforming Text Data
A3: 🎯 USE CASE: "Extract first name from full name, clean messy data, combine fields, extract parts of IDs"
A5: 🔧 SYNTAX REFERENCE
A6: Formula | B6: Syntax | E6: What It Does
A7: LEFT | B7: =LEFT(text, num_chars) | E7: Extracts characters from the start
A8: RIGHT | B8: =RIGHT(text, num_chars) | E8: Extracts characters from the end
A9: MID | B9: =MID(text, start_pos, num_chars) | E9: Extracts from the middle
A10: LEN | B10: =LEN(text) | E10: Returns length of text
A11: FIND | B11: =FIND(find_text, within_text) | E11: Finds position of text
A12: CONCATENATE | B12: =CONCATENATE(text1, text2, ...) | E12: Joins text together (also use &)
A13: TRIM | B13: =TRIM(text) | E13: Removes extra spaces
A14: PROPER | B14: =PROPER(text) | E14: Capitalizes first letter of each word
A15: UPPER/LOWER | B15: =UPPER(text) / =LOWER(text) | E15: Changes case
A18: 📊 LIVE DEMO — Real-World Text Scenarios
A19: Full Name | B19: First Name | C19: Last Name | D19: Email Generated | E19: FULL NAME
A20: Sarah Johnson | B20: =LEFT(A20,FIND(" ",A20)-1) -> Sarah | C20: =MID(A20,FIND(" ",A20)+1,100) -> Johnson | D20: =LOWER(B20)&"."&LOWER(C20)&"@company.com" -> sarah.johnson@company.com | E20: =_xlfn.CONCAT(B20," ",C20," ",D20) -> Sarah Johnson sarah.johnson@company.com
A21: Mike Chen | B21: =LEFT(A21,FIND(" ",A21)-1) -> Mike | C21: =MID(A21,FIND(" ",A21)+1,100) -> Chen | D21: =LOWER(B21)&"."&LOWER(C21)&"@company.com" -> mike.chen@company.com | E21: =_xlfn.CONCAT(B21," ",C21," ",D21) -> Mike Chen mike.chen@company.com
A22: Emma Wilson | B22: =LEFT(A22,FIND(" ",A22)-1) -> Emma | C22: =MID(A22,FIND(" ",A22)+1,100) -> Wilson | D22: =LOWER(B22)&"."&LOWER(C22)&"@company.com" -> emma.wilson@company.com | E22: =_xlfn.CONCAT(B22," ",C22," ",D22) -> Emma Wilson emma.wilson@company.com
A23: James Lee | B23: =LEFT(A23,FIND(" ",A23)-1) -> James | C23: =MID(A23,FIND(" ",A23)+1,100) -> Lee | D23: =LOWER(B23)&"."&LOWER(C23)&"@company.com" -> james.lee@company.com | E23: =_xlfn.CONCAT(B23," ",C23," ",D23) -> James Lee james.lee@company.com
A24: Priya Patel | B24: =LEFT(A24,FIND(" ",A24)-1) -> Priya | C24: =MID(A24,FIND(" ",A24)+1,100) -> Patel | D24: =LOWER(B24)&"."&LOWER(C24)&"@company.com" -> priya.patel@company.com | E24: =_xlfn.CONCAT(B24," ",C24," ",D24) -> Priya Patel priya.patel@company.com
A27: 🧹 DATA CLEANING DEMO
A28: Messy Data | B28: Cleaned | C28: Formula Used
A29: john smith | B29: =PROPER(TRIM(A29)) -> John Smith | C29: PROPER + TRIM
A30: SARAH JONES | B30: =PROPER(A30) -> Sarah Jones | C30: PROPER to fix ALL CAPS | G30: LEN | H30: FIND | I30: Result
A31: mike.chen | B31: =UPPER(LEFT(A31,1))&MID(A31,2,FIND(".",A31)-2)&" "&UPPER(MID(A31,FIND(".",A31)+1,1))&MID(A31,FIND(".",A31)+2,100) -> Mike Chen | C31: Complex extraction | G31: =LEN(D38) -> 13 | H31: =FIND(" ",D38) -> 6 | I31: =G31-H31 -> 7
A32: ORD-1045 | B32: =RIGHT(A32,4) -> 1045 | C32: RIGHT to get order number | G32: =LEN(D39) -> 9 | H32: =FIND(" ",D39) -> 5 | I32: =G32-H32 -> 4
A33: ORD-1045 | B33: =LEFT(A33,3) -> ORD | C33: LEFT to get prefix | G33: =LEN(D40) -> 14 | H33: =FIND(" ",D40) -> 8 | I33: =G33-H33 -> 6
A36: 🔗 COMBINING TEXT
A37: First | B37: Last | C37: Using & | D37: Using CONCATENATE | E37: FIRST NAME | F37: LAST NAME
A38: Sarah | B38: Johnson | C38: =A38&" "&B38 -> Sarah Johnson | D38: =CONCATENATE(A38," ",B38) -> Sarah Johnson | E38: =LEFT(D38,FIND(" ",D38)-1) -> Sarah | F38: =RIGHT(D38,LEN(D38)-FIND(" ",D38)) -> Johnson | G38: =LEFT(D38, FIND(" ", D38 & " ") - 1) -> Sarah
A39: Mike | B39: Chen | C39: =A39&" "&B39 -> Mike Chen | D39: =CONCATENATE(A39," ",B39) -> Mike Chen | E39: =LEFT(D39,FIND(" ",D39)-1) -> Mike | F39: =RIGHT(D39,LEN(D39)-FIND(" ",D39)) -> Chen | G39: =LEFT(D39, FIND(" ", D39 & " ") - 1) -> Mike
A40: Emma | B40: Wilson | C40: =A40&" "&B40 -> Emma Wilson | D40: Emmasss Wilson | E40: =LEFT(D40,FIND(" ",D40)-1) -> Emmasss | F40: =RIGHT(D40,LEN(D40)-FIND(" ",D40)) -> Wilson | G40: =LEFT(D40, FIND(" ", D40 & " ") - 1) -> Emmasss
A43: ✏️ TRY IT YOURSELF
A44: Your Task | E44: Write Your Formula Here
A45: Extract the order number (last 4 digits) from "ORD-1088" | E45: =RIGHT('Sales Data'!A7,4) -> 1088
A46: Combine city and state: "Sydney" + "NSW" → "Sydney, NSW" | E46: =_xlfn.CONCAT('Sales Data'!E14, " ",'Sales Data'!F14) -> Sydney NSW
A47: Clean this: " MESSY DATA " → "Messy Data" | E47: =TRIM(" MESSY DATA ") -> MESSY DATA

Sheet Sheet3
A1: Data returned for Sum of Final Amount ($), Dan Wilson (First 1000 rows).
A3: Table2[Order ID] | B3: Table2[Order Date] | C3: Table2[Customer Name] | D3: Table2[Email] | E3: Table2[City] | F3: Table2[State] | G3: Table2[Product] | H3: Table2[Category] | I3: Table2[Unit Price ($)] | J3: Table2[Quantity] | K3: Table2[Discount %] | L3: Table2[Total Before Discount ($)] | M3: Table2[Discount Amount ($)] | N3: Table2[Final Amount ($)] | O3: Table2[Status] | P3: Table2[Sales Rep] | Q3: Table2[Payment Method]
A4: ORD-1088 | B4: 45707 | C4: Priya Patel | D4: priya@email.com | E4: Adelaide | F4: SA | G4: Laptop | H4: Electronics | I4: 899.99 | J4: 5 | K4: 0.15 | L4: 4499.95 | M4: 674.9925 | N4: 3824.9575 | O4: Delivered | P4: Dan Wilson | Q4: PayPal
A5: ORD-1068 | B5: 45703 | C5: Sophie Martin | D5: sophie@email.com | E5: Melbourne | F5: VIC | G5: Standing Desk | H5: Furniture | I5: 499.99 | J5: 5 | K5: 0 | L5: 2499.95 | M5: 0 | N5: 2499.95 | O5: Processing | P5: Dan Wilson | Q5: Credit Card
A6: ORD-1078 | B6: 45854 | C6: Tom Brown | D6: tom@email.com | E6: Sydney | F6: NSW | G6: Laptop | H6: Electronics | I6: 899.99 | J6: 3 | K6: 0.2 | L6: 2699.97 | M6: 539.994 | N6: 2159.976 | O6: Delivered | P6: Dan Wilson | Q6: Credit Card
A7: ORD-1080 | B7: 45870 | C7: Tom Brown | D7: tom@email.com | E7: Sydney | F7: NSW | G7: Standing Desk | H7: Furniture | I7: 499.99 | J7: 4 | K7: 0.15 | L7: 1999.96 | M7: 299.994 | N7: 1699.966 | O7: Delivered | P7: Dan Wilson | Q7: PayPal
A8: ORD-1014 | B8: 45782 | C8: Ryan Nguyen | D8: ryan@email.com | E8: Adelaide | F8: SA | G8: Monitor 27" | H8: Electronics | I8: 349.99 | J8: 5 | K8: 0.1 | L8: 1749.95 | M8: 174.995 | N8: 1574.955 | O8: Delivered | P8: Dan Wilson | Q8: Credit Card
A9: ORD-1100 | B9: 45917 | C9: Lisa Wang | D9: lisa@email.com | E9: Melbourne | F9: VIC | G9: Desk Chair | H9: Furniture | I9: 299.99 | J9: 5 | K9: 0 | L9: 1499.95 | M9: 0 | N9: 1499.95 | O9: Delivered | P9: Dan Wilson | Q9: Bank Transfer
A10: ORD-1083 | B10: 45762 | C10: Tom Brown | D10: tom@email.com | E10: Sydney | F10: NSW | G10: Desk Chair | H10: Furniture | I10: 299.99 | J10: 4 | K10: 0 | L10: 1199.96 | M10: 0 | N10: 1199.96 | O10: Returned | P10: Dan Wilson | Q10: Bank Transfer
A11: ORD-1013 | B11: 45953 | C11: James Lee | D11: james@email.com | E11: Perth | F11: WA | G11: Desk Chair | H11: Furniture | I11: 299.99 | J11: 4 | K11: 0.05 | L11: 1199.96 | M11: 59.998 | N11: 1139.962 | O11: Processing | P11: Dan Wilson | Q11: PayPal
A12: ORD-1031 | B12: 45862 | C12: Mike Chen | D12: mike@email.com | E12: Melbourne | F12: VIC | G12: Desk Chair | H12: Furniture | I12: 299.99 | J12: 2 | K12: 0 | L12: 599.98 | M12: 0 | N12: 599.98 | O12: Delivered | P12: Dan Wilson | Q12: PayPal
A13: ORD-1097 | B13: 45674 | C13: Mike Chen | D13: mike@email.com | E13: Melbourne | F13: VIC | G13: Monitor 27" | H13: Electronics | I13: 349.99 | J13: 2 | K13: 0.15 | L13: 699.98 | M13: 104.997 | N13: 594.983 | O13: Delivered | P13: Dan Wilson | Q13: Credit Card
A14: ORD-1043 | B14: 45811 | C14: James Lee | D14: james@email.com | E14: Perth | F14: WA | G14: Headphones | H14: Electronics | I14: 129.99 | J14: 3 | K14: 0 | L14: 389.97 | M14: 0 | N14: 389.97 | O14: Delivered | P14: Dan Wilson | Q14: Credit Card
A15: ORD-1035 | B15: 45847 | C15: David Kim | D15: david@email.com | E15: Brisbane | F15: QLD | G15: Headphones | H15: Electronics | I15: 129.99 | J15: 3 | K15: 0.05 | L15: 389.97 | M15: 19.4985 | N15: 370.4715 | O15: Processing | P15: Dan Wilson | Q15: PayPal
... A25: ORD-1021 | B25: 45734 | C25: Anna Garcia | D25: anna@email.com | E25: Sydney | F25: NSW | G25: Printer Paper | H25: Office Supplies | I25: 24.99 | J25: 1 | K25: 0.1 | L25: 24.99 | M25: 2.499 | N25: 22.491 | O25: Delivered | P25: Dan Wilson | Q25: Credit Card

Sheet Sheet4
A1: Data returned for Sum of Final Amount ($), Bob Smith (First 1000 rows).
A3: Table2[Order ID] | B3: Table2[Order Date] | C3: Table2[Customer Name] | D3: Table2[Email] | E3: Table2[City] | F3: Table2[State] | G3: Table2[Product] | H3: Table2[Category] | I3: Table2[Unit Price ($)] | J3: Table2[Quantity] | K3: Table2[Discount %] | L3: Table2[Total Before Discount ($)] | M3: Table2[Discount Amount ($)] | N3: Table2[Final Amount ($)] | O3: Table2[Status] | P3: Table2[Sales Rep] | Q3: Table2[Payment Method] | R3: Table2[Order Date (Month)] | S3: Table2[Order Date (Month Index)]
A4: ORD-1084 | B4: 45704 | C4: Ryan Nguyen | D4: ryan@email.com | E4: Adelaide | F4: SA | G4: Laptop | H4: Electronics | I4: 899.99 | J4: 5 | K4: 0 | L4: 4499.95 | M4: 0 | N4: 4499.95 | O4: Delivered | P4: Bob Smith | Q4: Credit Card | R4: Feb | S4: 2
A5: ORD-1059 | B5: 46005 | C5: Anna Garcia | D5: anna@email.com | E5: Sydney | F5: NSW | G5: Laptop | H5: Electronics | I5: 899.99 | J5: 5 | K5: 0.15 | L5: 4499.95 | M5: 674.9925 | N5: 3824.9575 | O5: Processing | P5: Bob Smith | Q5: Bank Transfer | R5: Dec | S5: 12
A6: ORD-1001 | B6: 45965 | C6: Ryan Nguyen | D6: ryan@email.com | E6: Adelaide | F6: SA | G6: Laptop | H6: Electronics | I6: 899.99 | J6: 3 | K6: 0 | L6: 2699.97 | M6: 0 | N6: 2699.97 | O6: Delivered | P6: Bob Smith | Q6: Credit Card | R6: Nov | S6: 11
A7: ORD-1052 | B7: 45730 | C7: Emma Wilson | D7: emma@email.com | E7: Brisbane | F7: QLD | G7: Laptop | H7: Electronics | I7: 899.99 | J7: 3 | K7: 0.2 | L7: 2699.97 | M7: 539.994 | N7: 2159.976 | O7: Delivered | P7: Bob Smith | Q7: Bank Transfer | R7: Mar | S7: 3
A8: ORD-1003 | B8: 45695 | C8: Anna Garcia | D8: anna@email.com | E8: Sydney | F8: NSW | G8: Monitor 27" | H8: Electronics | I8: 349.99 | J8: 5 | K8: 0 | L8: 1749.95 | M8: 0 | N8: 1749.95 | O8: Shipped | P8: Bob Smith | Q8: Credit Card | R8: Feb | S8: 2
A9: ORD-1062 | B9: 45723 | C9: Sophie Martin | D9: sophie@email.com | E9: Melbourne | F9: VIC | G9: Standing Desk | H9: Furniture | I9: 499.99 | J9: 4 | K9: 0.15 | L9: 1999.96 | M9: 299.994 | N9: 1699.966 | O9: Processing | P9: Bob Smith | Q9: Credit Card | R9: Mar | S9: 3
A10: ORD-1026 | B10: 45750 | C10: Sarah Johnson | D10: sydney@email.com | E10: Sydney | F10: NSW | G10: Desk Chair | H10: Furniture | I10: 299.99 | J10: 5 | K10: 0.1 | L10: 1499.95 | M10: 149.995 | N10: 1349.955 | O10: Delivered | P10: Bob Smith | Q10: Credit Card | R10: Apr | S10: 4
A11: ORD-1051 | B11: 45833 | C11: Lisa Wang | D11: lisa@email.com | E11: Melbourne | F11: VIC | G11: Bookshelf | H11: Furniture | I11: 149.99 | J11: 5 | K11: 0.15 | L11: 749.95 | M11: 112.4925 | N11: 637.4575 | O11: Delivered | P11: Bob Smith | Q11: PayPal | R11: Jun | S11: 6
A12: ORD-1063 | B12: 45940 | C12: Anna Garcia | D12: anna@email.com | E12: Sydney | F12: NSW | G12: Standing Desk | H12: Furniture | I12: 499.99 | J12: 1 | K12: 0 | L12: 499.99 | M12: 0 | N12: 499.99 | O12: Delivered | P12: Bob Smith | Q12: Credit Card | R12: Oct | S12: 10
A13: ORD-1047 | B13: 45709 | C13: Priya Patel | D13: priya@email.com | E13: Adelaide | F13: SA | G13: Standing Desk | H13: Furniture | I13: 499.99 | J13: 1 | K13: 0 | L13: 499.99 | M13: 0 | N13: 499.99 | O13: Delivered | P13: Bob Smith | Q13: Bank Transfer | R13: Feb | S13: 2
A14: ORD-1049 | B14: 45996 | C14: Sarah Johnson | D14: sydney@email.com | E14: Sydney | F14: NSW | G14: Bookshelf | H14: Furniture | I14: 149.99 | J14: 3 | K14: 0.1 | L14: 449.97 | M14: 44.997 | N14: 404.973 | O14: Shipped | P14: Bob Smith | Q14: Credit Card | R14: Dec | S14: 12
A15: ORD-1054 | B15: 45774 | C15: David Kim | D15: david@email.com | E15: Brisbane | F15: QLD | G15: Headphones | H15: Electronics | I15: 129.99 | J15: 3 | K15: 0 | L15: 389.97 | M15: 0 | N15: 389.97 | O15: Returned | P15: Bob Smith | Q15: PayPal | R15: Apr | S15: 4
... A32: ORD-1010 | B32: 45970 | C32: Sophie Martin | D32: sophie@email.com | E32: Melbourne | F32: VIC | G32: Pen Set | H32: Office Supplies | I32: 8.99 | J32: 1 | K32: 0.1 | L32: 8.99 | M32: 0.899 | N32: 8.091 | O32: Processing | P32: Bob Smith | Q32: Credit Card | R32: Nov | S32: 11

Sheet Sheet5
A1: Data returned for Sum of Final Amount ($), Bob Smith (First 1000 rows).
A3: Table2[Order ID] | B3: Table2[Order Date] | C3: Table2[Customer Name] | D3: Table2[Email] | E3: Table2[City] | F3: Table2[State] | G3: Table2[Product] | H3: Table2[Category] | I3: Table2[Unit Price ($)] | J3: Table2[Quantity] | K3: Table2[Discount %] | L3: Table2[Total Before Discount ($)] | M3: Table2[Discount Amount ($)] | N3: Table2[Final Amount ($)] | O3: Table2[Status] | P3: Table2[Sales Rep] | Q3: Table2[Payment Method] | R3: Table2[Order Date (Month)] | S3: Table2[Order Date (Month Index)]
A4: ORD-1084 | B4: 45704 | C4: Ryan Nguyen | D4: ryan@email.com | E4: Adelaide | F4: SA | G4: Laptop | H4: Electronics | I4: 899.99 | J4: 5 | K4: 0 | L4: 4499.95 | M4: 0 | N4: 4499.95 | O4: Delivered | P4: Bob Smith | Q4: Credit Card | R4: Feb | S4: 2
A5: ORD-1059 | B5: 46005 | C5: Anna Garcia | D5: anna@email.com | E5: Sydney | F5: NSW | G5: Laptop | H5: Electronics | I5: 899.99 | J5: 5 | K5: 0.15 | L5: 4499.95 | M5: 674.9925 | N5: 3824.9575 | O5: Processing | P5: Bob Smith | Q5: Bank Transfer | R5: Dec | S5: 12
A6: ORD-1001 | B6: 45965 | C6: Ryan Nguyen | D6: ryan@email.com | E6: Adelaide | F6: SA | G6: Laptop | H6: Electronics | I6: 899.99 | J6: 3 | K6: 0 | L6: 2699.97 | M6: 0 | N6: 2699.97 | O6: Delivered | P6: Bob Smith | Q6: Credit Card | R6: Nov | S6: 11
A7: ORD-1052 | B7: 45730 | C7: Emma Wilson | D7: emma@email.com | E7: Brisbane | F7: QLD | G7: Laptop | H7: Electronics | I7: 899.99 | J7: 3 | K7: 0.2 | L7: 2699.97 | M7: 539.994 | N7: 2159.976 | O7: Delivered | P7: Bob Smith | Q7: Bank Transfer | R7: Mar | S7: 3
A8: ORD-1003 | B8: 45695 | C8: Anna Garcia | D8: anna@email.com | E8: Sydney | F8: NSW | G8: Monitor 27" | H8: Electronics | I8: 349.99 | J8: 5 | K8: 0 | L8: 1749.95 | M8: 0 | N8: 1749.95 | O8: Shipped | P8: Bob Smith | Q8: Credit Card | R8: Feb | S8: 2
A9: ORD-1062 | B9: 45723 | C9: Sophie Martin | D9: sophie@email.com | E9: Melbourne | F9: VIC | G9: Standing Desk | H9: Furniture | I9: 499.99 | J9: 4 | K9: 0.15 | L9: 1999.96 | M9: 299.994 | N9: 1699.966 | O9: Processing | P9: Bob Smith | Q9: Credit Card | R9: Mar | S9: 3
A10: ORD-1026 | B10: 45750 | C10: Sarah Johnson | D10: sydney@email.com | E10: Sydney | F10: NSW | G10: Desk Chair | H10: Furniture | I10: 299.99 | J10: 5 | K10: 0.1 | L10: 1499.95 | M10: 149.995 | N10: 1349.955 | O10: Delivered | P10: Bob Smith | Q10: Credit Card | R10: Apr | S10: 4
A11: ORD-1051 | B11: 45833 | C11: Lisa Wang | D11: lisa@email.com | E11: Melbourne | F11: VIC | G11: Bookshelf | H11: Furniture | I11: 149.99 | J11: 5 | K11: 0.15 | L11: 749.95 | M11: 112.4925 | N11: 637.4575 | O11: Delivered | P11: Bob Smith | Q11: PayPal | R11: Jun | S11: 6
A12: ORD-1063 | B12: 45940 | C12: Anna Garcia | D12: anna@email.com | E12: Sydney | F12: NSW | G12: Standing Desk | H12: Furniture | I12: 499.99 | J12: 1 | K12: 0 | L12: 499.99 | M12: 0 | N12: 499.99 | O12: Delivered | P12: Bob Smith | Q12: Credit Card | R12: Oct | S12: 10
A13: ORD-1047 | B13: 45709 | C13: Priya Patel | D13: priya@email.com | E13: Adelaide | F13: SA | G13: Standing Desk | H13: Furniture | I13: 499.99 | J13: 1 | K13: 0 | L13: 499.99 | M13: 0 | N13: 499.99 | O13: Delivered | P13: Bob Smith | Q13: Bank Transfer | R13: Feb | S13: 2
A14: ORD-1049 | B14: 45996 | C14: Sarah Johnson | D14: sydney@email.com | E14: Sydney | F14: NSW | G14: Bookshelf | H14: Furniture | I14: 149.99 | J14: 3 | K14: 0.1 | L14: 449.97 | M14: 44.997 | N14: 404.973 | O14: Shipped | P14: Bob Smith | Q14: Credit Card | R14: Dec | S14: 12
A15: ORD-1054 | B15: 45774 | C15: David Kim | D15: david@email.com | E15: Brisbane | F15: QLD | G15: Headphones | H15: Electronics | I15: 129.99 | J15: 3 | K15: 0 | L15: 389.97 | M15: 0 | N15: 389.97 | O15: Returned | P15: Bob Smith | Q15: PayPal | R15: Apr | S15: 4
... A32: ORD-1010 | B32: 45970 | C32: Sophie Martin | D32: sophie@email.com | E32: Melbourne | F32: VIC | G32: Pen Set | H32: Office Supplies | I32: 8.99 | J32: 1 | K32: 0.1 | L32: 8.99 | M32: 0.899 | N32: 8.091 | O32: Processing | P32: Bob Smith | Q32: Credit Card | R32: Nov | S32: 11

Sheet Sheet6
A1: Data returned for Sum of Final Amount ($), Bob Smith (First 1000 rows).
A3: Table2[Order ID] | B3: Table2[Order Date] | C3: Table2[Customer Name] | D3: Table2[Email] | E3: Table2[City] | F3: Table2[State] | G3: Table2[Product] | H3: Table2[Category] | I3: Table2[Unit Price ($)] | J3: Table2[Quantity] | K3: Table2[Discount %] | L3: Table2[Total Before Discount ($)] | M3: Table2[Discount Amount ($)] | N3: Table2[Final Amount ($)] | O3: Table2[Status] | P3: Table2[Sales Rep] | Q3: Table2[Payment Method] | R3: Table2[Order Date (Month)] | S3: Table2[Order Date (Month Index)]
A4: ORD-1084 | B4: 45704 | C4: Ryan Nguyen | D4: ryan@email.com | E4: Adelaide | F4: SA | G4: Laptop | H4: Electronics | I4: 899.99 | J4: 5 | K4: 0 | L4: 4499.95 | M4: 0 | N4: 4499.95 | O4: Delivered | P4: Bob Smith | Q4: Credit Card | R4: Feb | S4: 2
A5: ORD-1059 | B5: 46005 | C5: Anna Garcia | D5: anna@email.com | E5: Sydney | F5: NSW | G5: Laptop | H5: Electronics | I5: 899.99 | J5: 5 | K5: 0.15 | L5: 4499.95 | M5: 674.9925 | N5: 3824.9575 | O5: Processing | P5: Bob Smith | Q5: Bank Transfer | R5: Dec | S5: 12
A6: ORD-1001 | B6: 45965 | C6: Ryan Nguyen | D6: ryan@email.com | E6: Adelaide | F6: SA | G6: Laptop | H6: Electronics | I6: 899.99 | J6: 3 | K6: 0 | L6: 2699.97 | M6: 0 | N6: 2699.97 | O6: Delivered | P6: Bob Smith | Q6: Credit Card | R6: Nov | S6: 11
A7: ORD-1052 | B7: 45730 | C7: Emma Wilson | D7: emma@email.com | E7: Brisbane | F7: QLD | G7: Laptop | H7: Electronics | I7: 899.99 | J7: 3 | K7: 0.2 | L7: 2699.97 | M7: 539.994 | N7: 2159.976 | O7: Delivered | P7: Bob Smith | Q7: Bank Transfer | R7: Mar | S7: 3
A8: ORD-1003 | B8: 45695 | C8: Anna Garcia | D8: anna@email.com | E8: Sydney | F8: NSW | G8: Monitor 27" | H8: Electronics | I8: 349.99 | J8: 5 | K8: 0 | L8: 1749.95 | M8: 0 | N8: 1749.95 | O8: Shipped | P8: Bob Smith | Q8: Credit Card | R8: Feb | S8: 2
A9: ORD-1062 | B9: 45723 | C9: Sophie Martin | D9: sophie@email.com | E9: Melbourne | F9: VIC | G9: Standing Desk | H9: Furniture | I9: 499.99 | J9: 4 | K9: 0.15 | L9: 1999.96 | M9: 299.994 | N9: 1699.966 | O9: Processing | P9: Bob Smith | Q9: Credit Card | R9: Mar | S9: 3
